Workbook
Name Slicer_Channel: #N/A
Name Slicer_Month: #N/A
Name Slicer_Region: #N/A
Name Slicer_Region1: #N/A
Name Slicer_Region2: #N/A
Name Slicer_Year: #N/A

Sheet Raw_Data
A1: RAW DATA — 20_Marketing (Original Source)
A2: DO NOT MODIFY — preserved exactly as supplied by the lecturer.
A3: Campaign_ID | B3: Start_Date | C3: Channel | D3: Region | E3: Budget | F3: Leads | G3: Conversions
A4: CMP0268 | B4: 46077 | C4: Search | D4: Mogadishu | E4: 1902.8 | F4: 258 | G4: 58
A5: CMP0077 | B5: 46186 | D5: Mogadishu | E5: 2408.15 | F5: 408 | G5: 89
A6: CMP0207 | B6: 46153 | D6: Kismayo | E6: 2635.33 | F6: 573 | G6: 100
B7: 46005 | C7: Social Media | D7: Kismayo | E7: 3036.06 | F7: 350 | G7: 61
A8: CMP0089 | B8: 45732 | C8: Social Media | D8: Hargeisa | E8: 4857.89 | F8: 742 | G8: 131
A9: CMP0098 | B9: 45772 | C9: Influencer | E9: 2904.04 | F9: 2013 | G9: 81
A10: CMP0206 | B10: 46185 | C10: Search | D10: Garowe | E10: 518.97 | F10: 101 | G10: 20
A11: CMP0094 | B11: 46146 | C11: Influencer | D11: Hargeisa | E11: 3151.53 | F11: 510 | G11: 74
A12: CMP0270 | B12: 46093 | C12: Email | D12: Kismayo | E12: 2558.6 | F12: 542 | G12: 109
A13: CMP0132 | B13: 45886 | C13: Search | D13: Garowe | E13: 2993.64 | F13: 602 | G13: 170
A14: CMP0169 | B14: 45757 | C14: Social Media | D14: Hargeisa | E14: 3988.62 | F14: 656 | G14: 121
A15: CMP0082 | B15: 45888 | C15: Search | E15: 4275.45 | F15: 604 | G15: 169
A16: CMP0179 | B16: 46144 | C16: Search | D16: Garowe | E16: 2086.02 | F16: 273 | G16: 88
A17: CMP0083 | B17: 46100 | C17: Search | D17: Garowe | E17: 2263.59 | F17: 309 | G17: 69
A18: CMP0141 | B18: 45888 | C18: Search | D18: Garowe | E18: 2431.87 | F18: 576 | G18: 181
A19: CMP0005 | B19: 45681 | C19: Search | D19: Mogadishu | F19: 433 | G19: 113
A20: CMP0212 | B20: 45903 | C20: Unknown | D20: Mogadishu | E20: 3520.5 | F20: 659 | G20: 130
A21: CMP0049 | B21: 46153 | D21: Baidoa | E21: 4913.8 | F21: 799 | G21: 60
A22: CMP0281 | B22: 45860 | C22: Email | E22: 3753.98 | F22: 334 | G22: 55
A23: CMP0061 | B23: 45955 | C23: Search | D23: Mogadishu | E23: 457.9 | F23: 42 | G23: 10
A24: CMP0125 | B24: 46228 | C24: Search | D24: Hargeisa | E24: 4532.21 | F24: 843 | G24: 163
A25: CMP0266 | B25: 45811 | C25: Social Media | D25: Hargeisa | E25: 4633.21 | G25: 92
A26: CMP0050 | B26: 46168 | C26: Social Media | D26: Mogadishu | E26: 2503.33 | F26: 297 | G26: 53
A27: CMP0275 | C27: Influencer | D27: Mogadishu | E27: 2370.21 | F27: 553 | G27: 120
A28: CMP0160 | B28: 45834 | C28: Email | D28: Bosaso | E28: 4663.53 | F28: 641 | G28: 109
A29: CMP0239 | B29: 46005 | C29: Influencer | D29: Mogadishu | E29: 658.72 | F29: 52 | G29: 8
A30: CMP0119 | B30: 46056 | C30: Influencer | D30: Mogadishu | E30: 2413.8 | F30: 574 | G30: 95
A31: CMP0232 | B31: 45771 | C31: Social Media | D31: Baidoa | E31: 1496.59 | F31: 223 | G31: 36
A32: CMP0262 | B32: 46050 | C32: Influencer | E32: 3057.48 | F32: 503 | G32: 73
A33: CMP0291 | B33: 45662 | C33: Search | D33: Bosaso | F33: 118 | G33: 25
A34: CMP0152 | C34: Social Media | D34: Mogadishu | E34: 4668.73 | F34: 537 | G34: 48
A35: CMP0090 | B35: 45800 | C35: Influencer | D35: Hargeisa | E35: 994.02 | G35: 33
A36: CMP0271 | B36: 45988 | C36: Search | D36: Garowe | E36: 4865.12 | F36: 463 | G36: 137
A37: CMP0227 | B37: 46131 | C37: Email | D37: Mogadishu | E37: 2693.81 | F37: 533 | G37: 83
A38: CMP0238 | B38: 45678 | C38: Social Media | D38: Hargeisa | E38: 2861.6 | F38: 388 | G38: 63
A39: CMP0107 | B39: 45861 | C39: Search | D39: Garowe | E39: 480.1 | F39: 76 | G39: 16
A40: CMP0023 | B40: 45795 | C40: Search | D40: Baidoa | E40: 3712.61 | F40: 420
...

Sheet Clean_Data
A1: CLEAN DATA — Standardized & Analysis-Ready
A3: Campaign_ID | B3: Start_Date | C3: Channel | D3: Region | E3: Budget | F3: Leads | G3: Conversions | H3: Year | I3: Month | J3: Conversion_Rate | K3: Campaign_Performance | L3: Cost_per_Lead | M3: Cost_per_Conversion | O3: CLEANING LOG
A4: CMP0268 | B4: 46077 | C4: Search | D4: Mogadishu | E4: 1902.8 | F4: 258 | G4: 58 | H4: 2026 | I4: 2 | J4: 0.2248062 | K4: High | L4: 7.3751938 | M4: 32.806897 | O4: Duplicate records removed | P4: 7
A5: CMP0077 | B5: 46186 | C5: Unknown | D5: Mogadishu | E5: 2408.15 | F5: 408 | G5: 89 | H5: 2026 | I5: 6 | J5: 0.21813725 | K5: High | L5: 5.9023284 | M5: 27.057865 | O5: Original records | P5: 300
A6: CMP0207 | B6: 46153 | C6: Unknown | D6: Kismayo | E6: 2635.33 | F6: 573 | G6: 100 | H6: 2026 | I6: 5 | J6: 0.17452007 | K6: Low | L6: 4.5991798 | M6: 26.3533 | O6: Clean records | P6: 293
A7: NEW0001 | B7: 46005 | C7: Social Media | D7: Kismayo | E7: 3036.06 | F7: 350 | G7: 61 | H7: 2025 | I7: 12 | J7: 0.17428571 | K7: Low | L7: 8.6744571 | M7: 49.771475 | O7: Missing categorical values | P7: Filled with Unknown
A8: CMP0089 | B8: 45732 | C8: Social Media | D8: Hargeisa | E8: 4857.89 | F8: 742 | G8: 131 | H8: 2025 | I8: 3 | J8: 0.17654987 | K8: Low | L8: 6.5470216 | M8: 37.08313 | O8: Missing numeric values | P8: Filled with median
A9: CMP0098 | B9: 45772 | C9: Influencer | D9: Unknown | E9: 2904.04 | F9: 2013 | G9: 81 | H9: 2025 | I9: 4 | J9: 0.04023845 | K9: Low | L9: 1.4426428 | M9: 35.852346 | O9: Missing dates | P9: Filled with median date
A10: CMP0206 | B10: 46185 | C10: Search | D10: Garowe | E10: 518.97 | F10: 101 | G10: 20 | H10: 2026 | I10: 6 | J10: 0.1980198 | K10: High | L10: 5.1383168 | M10: 25.9485 | O10: Text standardization | P10: TRIM + case normalization
A11: CMP0094 | B11: 46146 | C11: Influencer | D11: Hargeisa | E11: 3151.53 | F11: 510 | G11: 74 | H11: 2026 | I11: 5 | J11: 0.14509804 | K11: Low | L11: 6.1794706 | M11: 42.588243 | O11: Derived fields | P11: Year, Month, Conversion Rate, Performance, Cost metrics
A12: CMP0270 | B12: 46093 | C12: Email | D12: Kismayo | E12: 2558.6 | F12: 542 | G12: 109 | H12: 2026 | I12: 3 | J12: 0.20110701 | K12: High | L12: 4.7206642 | M12: 23.473394
A13: CMP0132 | B13: 45886 | C13: Search | D13: Garowe | E13: 2993.64 | F13: 602 | G13: 170 | H13: 2025 | I13: 8 | J13: 0.28239203 | K13: High | L13: 4.9728239 | M13: 17.609647
A14: CMP0169 | B14: 45757 | C14: Social Media | D14: Hargeisa | E14: 3988.62 | F14: 656 | G14: 121 | H14: 2025 | I14: 4 | J14: 0.18445122 | K14: Low | L14: 6.0802134 | M14: 32.963802
A15: CMP0082 | B15: 45888 | C15: Search | D15: Unknown | E15: 4275.45 | F15: 604 | G15: 169 | H15: 2025 | I15: 8 | J15: 0.27980132 | K15: High | L15: 7.0785596 | M15: 25.298521
A16: CMP0179 | B16: 46144 | C16: Search | D16: Garowe | E16: 2086.02 | F16: 273 | G16: 88 | H16: 2026 | I16: 5 | J16: 0.32234432 | K16: High | L16: 7.6410989 | M16: 23.704773
A17: CMP0083 | B17: 46100 | C17: Search | D17: Garowe | E17: 2263.59 | F17: 309 | G17: 69 | H17: 2026 | I17: 3 | J17: 0.22330097 | K17: High | L17: 7.325534 | M17: 32.805652
A18: CMP0141 | B18: 45888 | C18: Search | D18: Garowe | E18: 2431.87 | F18: 576 | G18: 181 | H18: 2025 | I18: 8 | J18: 0.31423611 | K18: High | L18: 4.2219965 | M18: 13.435746
A19: CMP0005 | B19: 45681 | C19: Search | D19: Mogadishu | E19: 2869.495 | F19: 433 | G19: 113 | H19: 2025 | I19: 1 | J19: 0.26096998 | K19: High | L19: 6.6270092 | M19: 25.393761
A20: CMP0212 | B20: 45903 | C20: Unknown | D20: Mogadishu | E20: 3520.5 | F20: 659 | G20: 130 | H20: 2025 | I20: 9 | J20: 0.19726859 | K20: High | L20: 5.3421851 | M20: 27.080769
A21: CMP0049 | B21: 46153 | C21: Unknown | D21: Baidoa | E21: 4913.8 | F21: 799 | G21: 60 | H21: 2026 | I21: 5 | J21: 0.075093867 | K21: Low | L21: 6.1499374 | M21: 81.896667
A22: CMP0281 | B22: 45860 | C22: Email | D22: Unknown | E22: 3753.98 | F22: 334 | G22: 55 | H22: 2025 | I22: 7 | J22: 0.16467066 | K22: Low | L22: 11.239461 | M22: 68.254182
A23: CMP0061 | B23: 45955 | C23: Search | D23: Mogadishu | E23: 457.9 | F23: 42 | G23: 10 | H23: 2025 | I23: 10 | J23: 0.23809524 | K23: High | L23: 10.902381 | M23: 45.79
... A296: CMP0037 | B296: 45887 | C296: Influencer | D296: Unknown | E296: 4177.41 | F296: 427 | G296: 69 | H296: 2025 | I296: 8 | J296: 0.16159251 | K296: Low | L296: 9.7831616 | M296: 60.542174
E302: =SUM(E4:E296) -> 821022.84

Sheet Sheet9
A3: Row Labels | B3: Sum of Budget
A4: Email | B4: 112384.87
A5: Influencer | B5: 101777.99
A6: Radio | B6: 109347.25
A7: Search | B7: 210050.28
A8: Social Media | B8: 233155.52
A9: Unknown | B9: 54306.93
A10: Grand Total | B10: 821022.83
A21: Row Labels | B21: Count of Region
A22: 2025 | B22: 190
A23: 2026 | B23: 103
A24: Grand Total | B24: 293

Sheet dhasbord2

Sheet Analysis
A1: ANALYSIS — Formula Demonstration & Key Metrics
A3: Metric | B3: Formula | C3: Result | E3: REQUIRED FUNCTIONS
A4: Total Budget | B4: =SUM(Clean_Data!E4:E296) -> 821022.84 | C4: =SUM(Clean_Data!E4:E296) -> 821022.84 | E4: SUM | F4: =SUM(Clean_Data!E4:E296) -> 821022.84 | G4: Total budget
A5: Average Budget | B5: =AVERAGE(Clean_Data!E4:E296) -> 2802.1257 | C5: =AVERAGE(Clean_Data!E4:E296) -> 2802.1257 | E5: AVERAGE | F5: =AVERAGE(Clean_Data!E4:E296) -> 2802.1257 | G5: Average budget
A6: Campaign Records | B6: =COUNT(Clean_Data!E4:E296) -> 293 | C6: =COUNT(Clean_Data!E4:E296) -> 293 | E6: COUNT | F6: =COUNT(Clean_Data!E4:E296) -> 293 | G6: Count
A7: Minimum Budget | B7: =MIN(Clean_Data!E4:E296) -> -9 | C7: =MIN(Clean_Data!E4:E296) -> -9 | E7: MIN | F7: =MIN(Clean_Data!E4:E296) -> -9 | G7: Minimum
A8: Maximum Budget | B8: =MAX(Clean_Data!E4:E296) -> 10024 | C8: =MAX(Clean_Data!E4:E296) -> 10024 | E8: MAX | F8: =MAX(Clean_Data!E4:E296) -> 10024 | G8: Maximum
A9: Total Leads | B9: =SUM(Clean_Data!F4:F296) -> 134724 | C9: =SUM(Clean_Data!F4:F296) -> 134724 | E9: SUMIF | F9: =SUMIF(Clean_Data!C4:C296,"Search",Clean_Data!E4:E296) -> 210050.28 | G9: Search budget
A10: Total Conversions | B10: =SUM(Clean_Data!G4:G296) -> 24658 | C10: =SUM(Clean_Data!G4:G296) -> 24658 | E10: COUNTIF | F10: =COUNTIF(Clean_Data!C4:C296,"Search") -> 81 | G10: Search campaigns
A11: Overall Conversion Rate | B11: =SUM(Clean_Data!G4:G296)/SUM(Clean_Data!F4:F296) -> 0.18302604 | C11: =SUM(Clean_Data!G4:G296)/SUM(Clean_Data!F4:F296) -> 0.18302604 | E11: AVERAGEIF | F11: =AVERAGEIF(Clean_Data!C4:C296,"Search",Clean_Data!E4:E296) -> 2593.2134 | G11: Average Search budget
A12: Average Conversion Rate | B12: =AVERAGE(Clean_Data!J4:J296) -> 0.19664224 | C12: =AVERAGE(Clean_Data!J4:J296) -> 0.19664224 | E12: IF | F12: =IF(J4>=0.2,"High","Low") -> Low | G12: Performance classification
A13: Average Cost/Lead | B13: =AVERAGE(Clean_Data!L4:L296) -> 7.0090318 | C13: =AVERAGE(Clean_Data!L4:L296) -> 7.0090318 | E13: AND | F13: =IF(AND(J4>=0.2,L4<5),"Efficient","Review") -> Review | G13: Combined logic
E14: TODAY | F14: =TODAY() -> 46261 | G14: Current date
E15: YEAR | F15: =YEAR(B4) -> 4147 | G15: Year
E16: MONTH | F16: =MONTH(B4) -> 11 | G16: Month
E17: DAY | F17: =DAY(B4) -> 17 | G17: Day
E18: NETWORKDAYS | F18: =NETWORKDAYS(B4,TODAY()) -> -553402 | G18: Working days
E19: TRIM | F19: =TRIM(C4) -> 821022.835000001 | G19: Text spaces
E20: UPPER | F20: =UPPER(C4) -> 821022.835000001 | G20: Uppercase
E21: PROPER | F21: =PROPER(D4) | G21: Proper case
E22: SUBSTITUTE | F22: =SUBSTITUTE(C4," ","_") -> 821022.835000001 | G22: Replace text

Sheet PivotTables
A1: PIVOTTABLES — Marketing Performance
A2: These summaries are PivotTable-ready: Rows / Columns / Values / Filters are documented below.
I3: Filter
A4: PIVOT 1 — CHANNEL PERFORMANCE | I4: Year | J4: - all -
A5: Channel | B5: Campaigns | C5: Budget | D5: Leads | E5: Conversions | F5: Conversion Rate
A6: Email | B6: 41 | C6: 112384.87 | D6: 18307 | E6: 3724 | F6: 0.20341946 | I6: Channel | J6: Data
A7: Influencer | B7: 37 | C7: 101777.99 | D7: 17241 | E7: 2755 | F7: 0.15979352 | I7: Email | J7: Sum - Budget | K7: 112384.87
A8: Radio | B8: 34 | C8: 109347.26 | D8: 16636 | E8: 1780 | F8: 0.10699687 | J8: Sum - Leads | K8: 18307
A9: Search | B9: 81 | C9: 210050.29 | D9: 36249 | E9: 8434 | F9: 0.23266849 | J9: Sum - Conversions | K9: 3724
A10: Social Media | B10: 82 | C10: 233155.52 | D10: 36259 | E10: 5765 | F10: 0.15899501 | I10: Influencer | J10: Sum - Budget | K10: 101777.99
A11: Unknown | B11: 18 | C11: 54306.93 | D11: 10032 | E11: 2200 | F11: 0.21929825 | J11: Sum - Leads | K11: 17241
J12: Sum - Conversions | K12: 2755
I13: Radio | J13: Sum - Budget | K13: 109347.26
A14: PIVOT 2 — REGIONAL PERFORMANCE | J14: Sum - Leads | K14: 16636
A15: Region | B15: Campaigns | C15: Budget | D15: Leads | E15: Conversions | F15: Conversion Rate | J15: Sum - Conversions | K15: 1780
A16: Baidoa | B16: 29 | C16: 88381.47 | D16: 13288 | E16: 2533 | F16: 0.19062312 | I16: Search | J16: Sum - Budget | K16: 210050.29
A17: Bosaso | B17: 38 | C17: 99953.34 | D17: 16808 | E17: 3457 | F17: 0.20567587 | J17: Sum - Leads | K17: 36249
A18: Garowe | B18: 26 | C18: 73376.21 | D18: 11888 | E18: 2405 | F18: 0.20230485 | J18: Sum - Conversions | K18: 8434
A19: Hargeisa | B19: 59 | C19: 168177.14 | D19: 26153 | E19: 4565 | F19: 0.17454976 | I19: Social Media | J19: Sum - Budget | K19: 233155.52
A20: Kismayo | B20: 32 | C20: 86475.55 | D20: 14361 | E20: 2634 | F20: 0.18341341 | J20: Sum - Leads | K20: 36259
A21: Mogadishu | B21: 93 | C21: 253404.54 | D21: 44435 | E21: 7942 | F21: 0.17873298 | I21: Filter
A22: Unknown | B22: 16 | C22: 51254.58 | D22: 7791 | E22: 1122 | F22: 0.14401232 | I22: Channel | J22: - all -
I24: Region | J24: Data
A25: PIVOT 3 — YEAR PERFORMANCE | I25: Baidoa | J25: Sum - Budget | K25: 88381.47
A26: Year | B26: Campaigns | C26: Budget | D26: Leads | E26: Conversions | F26: Conversion Rate | J26: Sum - Leads | K26: 13288
A27: 2025 | B27: 190 | C27: 534903.77 | D27: 87542 | E27: 15533 | F27: 0.17743483 | J27: Sum - Conversions | K27: 2533
A28: 2026 | B28: 103 | C28: 286119.07 | D28: 47182 | E28: 9125 | F28: 0.19340003 | I28: Bosaso | J28: Sum - Budget | K28: 99953.34
J29: Sum - Leads | K29: 16808
J30: Sum - Conversions | K30: 3457
A31: PIVOT 4 — MONTHLY PERFORMANCE | I31: Garowe | J31: Sum - Budget | K31: 73376.21
A32: MonthName | B32: Leads | C32: Conversions | J32: Sum - Leads | K32: 11888
A33: January | B33: 14257 | C33: 3027 | J33: Sum - Conversions | K33: 2405
A34: February | B34: 10929 | C34: 1711 | I34: Hargeisa | J34: Sum - Budget | K34: 168177.14
A35: March | B35: 14672 | C35: 2689 | J35: Sum - Leads | K35: 26153
A36: April | B36: 13562 | C36: 2395 | J36: Sum - Conversions | K36: 4565
A37: May | B37: 13348 | C37: 2209 | I37: Kismayo | J37: Sum - Budget | K37: 86475.55
A38: June | B38: 10159 | C38: 2016 | J38: Sum - Leads | K38: 14361
A39: July | B39: 16763 | C39: 2863 | I39: Filter
A40: August | B40: 7455 | C40: 1622 | I40: Region | J40: - all -
A41: September | B41: 8354 | C41: 1605
...

Sheet Dashboard1
A1: MARKETING EFFICIENCY DASHBOARD
A4: TOTAL BUDGET | D4: TOTAL LEADS | G4: TOTAL CONVERSIONS | J4: CONVERSION RATE
A5: =Analysis!C4 -> 821022.84 | D5: =Analysis!C9 -> 134724 | G5: =Analysis!C10 -> 24658 | J5: =Analysis!C11 -> 0.18302604
A9: Channel | B9: Cost / Lead | C9: Cost / Conversion | E9: Month | F9: Conversions | I9: Region | J9: Conversion Rate
A10: Row Labels | B10: Count of Channel | E10: Row Labels | F10: Sum of Month | I10: Row Labels | J10: Count of Region | K10: Sum of Budget
A11: Email | B11: 5 | E11: Baidoa | F11: 174 | I11: Baidoa | J11: 9 | K11: 25952.7
A12: Influencer | B12: 3 | E12: Bosaso | F12: 219 | I12: Bosaso | J12: 11 | K12: 30320.475
A13: Radio | B13: 6 | E13: Garowe | F13: 154 | I13: Garowe | J13: 12 | K13: 32950.06
A14: Search | B14: 8 | E14: Hargeisa | F14: 359 | I14: Hargeisa | J14: 18 | K14: 57982.595
A15: Social Media | B15: 8 | E15: Kismayo | F15: 200 | I15: Kismayo | J15: 11 | K15: 24963.975
A16: Unknown | B16: 2 | E16: Mogadishu | F16: 529 | I16: Mogadishu | J16: 36 | K16: 103130.65
A17: Grand Total | B17: 32 | E17: Unknown | F17: 94 | I17: Unknown | J17: 6 | K17: 10818.61
E18: Grand Total | F18: 1729 | I18: Grand Total | J18: 103 | K18: 286119.06

Sheet Findings
A1: FINDINGS & RECOMMENDATIONS
A4: FINDINGS
A5: 1. Search generated the highest conversion volume (8,434) among the channels.
A6: 2. Radio had the lowest conversion rate (10.7%) among the channels, indicating an area for optimization.
A7: 3. Bosaso recorded the strongest regional conversion rate (20.6%).
A8: 4. Total cleaned campaigns = 293; duplicate records removed = 7.
A9: 5. Overall conversion rate is 18.3%, giving management a high-level efficiency benchmark.
A12: RECOMMENDATIONS
A13: 1. Gradually increase investment in high-performing channels such as Search, while monitoring cost per lead and conversion rate.
A14: 2. Review the Radio campaign strategy, creative, targeting and landing experience to improve conversion efficiency.
A15: 3. Document and replicate the practices used in Bosaso where conversion efficiency is strongest, then test them in other regions.
A18: PROJECT WORKFLOW
A19: RAW DATA → CLEAN DATA → FORMULAS → PIVOTTABLES → CHARTS → KPIs → SLICERS → DASHBOARDS → FINDINGS → RECOMMENDATIONS
